Workbook

Sheet Read me
A1: Constraint and vendor scoring workbook
A2: Everything downstream of the address: the domain register, the seam register, the project register with domains assigned, an impact cascade that counts the affected applications, objects, interfaces, components and markets from the links you already keep, the constraint register with source, test, expiry and closure status, and a vendor scoring model with mandatory criteria and written anchors.
A4: The sheets
A5: Domains - eight to fifteen at group level. Owner, architect, core objects, three lines of target direction.
A6: Seams - where two domains argue. Who leads, who is consulted, what triggers a joint review.
A7: Projects - one row per initiative, with its primary domain, domains touched, route, and its cascade counts computed.
A8: Landscape - the link table the cascade reads: domain to application, application to object, interface, component, market.
A9: Constraints - five to eight per project, each with a source, a test, an expiry and a closure status.
A10: Vendor scoring - mandatory criteria, weighted criteria with anchors, and a computed result per vendor.
A12: How to run it
A13: 1. Fill Domains first. If you cannot name the owner of each without looking, there are too many or some are not real.
A14: 2. Write the seam register. An afternoon, and it is the artifact people quote back at you first.
... A25: Companion article: mehdibamou.com/publications/every-project-needs-an-address - free to use and adapt

Sheet Settings
A1: Setting | B1: Value | C1: Note
A2: As-at date | B2: 46203 | C2: Drives expiry countdowns
A3: Domain count ceiling | B3: 15 | C3: Above this, nobody can hold the list
A4: Constraints per project ceiling | B4: 8 | C4: Above this, none get read
A5: Address assignment target (days) | B5: 2 | C5: From intake. It takes about four minutes
A6: Architecture share of vendor score | B6: 0.28 | C6: Twenty-five to thirty per cent, or it does not matter

Sheet Lists
A1: Build | B1: Intake | C1: Open | D1: Principle | E1: Domain to application | F1: Mandatory
A2: Buy | B2: Funding decision | C2: Met | D2: Pattern | E2: Application to object | F2: Weighted
A3: Extend what exists | B3: Definition | C3: Deviated - exception registered | D3: Board decision | E3: Application to interface | F3: Desirable
A4: Unknown | B4: Execution | C4: Withdrawn | D4: Integration standard | E4: Application to component
B5: Closed | D5: Law or regulation | E5: Application to market

Sheet Domains
A1: Dom ID | B1: Domain | C1: Owner | D1: Architect | E1: Capabilities covered | F1: Core objects mastered | G1: Target direction (three lines) | H1: Known seams
A2: DOM-01 | B2: Customer management | C2: Head of CRM | D2: Named | E2: Customer acquisition, loyalty, service | F2: Customer, consent | G2: One customer identity across channels; commerce masters nothing; consent recorded once and read everywhere | H2: S-02
A3: DOM-02 | B3: Product management | C3: Head of product data | D3: Named | E3: Assortment, product data, lifecycle | F3: Material | G3: One material master; market variants as attributes, not as records | H3: S-06
A4: DOM-03 | B4: Source to contract | C4: Head of procurement ops | D4: Named | E4: Supplier qualification, sourcing, contract management | F4: Supplier, contract | G4: One supplier master with market registers retained under contract; contract lifecycle moves to the contract system next year | H4: S-01, S-04
A5: DOM-04 | B5: Order to cash | C5: Head of order management | D5: Named | E5: Order capture, fulfilment, invoicing | F5: Sales order | G5: Order capture converges on the core; no new local order stores | H5: S-01
A6: DOM-05 | B6: Pricing and promotion | C6: Head of pricing | D6: Named | E6: List pricing, conditions, promotions | F6: Price, promotion | G6: Pricing moves side-by-side; promotion stays in the promotion tool until wave three | H6: S-06
A7: DOM-06 | B7: Logistics | C7: Head of supply chain | D7: Named | E7: Warehousing, transport, stock | F7: Stock movement | G7: One stock ledger; market warehouse systems integrate on released contracts | H7: S-03
A8: DOM-07 | B8: Store operations | C8: Head of store ops | D8: Named | E8: Store execution, workforce, point of sale | F8: Store | G8: Store systems consume, never master, product and price | H8: S-03
A9: DOM-08 | B9: People operations | C9: Head of HR ops | D9: Named | E9: Hire to retire, payroll, org data | F9: Employee | G9: One employee record; payroll stays per country as a transition state | H9: S-05
A10: DOM-09 | B10: Finance operations | C10: Head of controlling | D10: Named | E10: Record to report, treasury, tax | F10: Cost centre, journal | G10: Finance consumes; it does not master operational objects | H10: S-01
A11: DOM-10 | B11: Corporate platforms | C11: CTO office | D11: Named | E11: Identity, collaboration, integration, data platform | F11: (none - it serves the others) | G11: Platforms are offered as services with contracts, not imposed | H11: S-05
A33: The test: can you name the owner of each without opening a document? If not, there are too many, or some are not real.

Sheet Seams
A1: Ref | B1: The seam | C1: Leads | D1: Consulted | E1: Trigger for a joint review | F1: Last disputed
A2: S-01 | B2: The invoice - where an order becomes a payable | C2: DOM-04 Order to cash | D2: DOM-09 Finance, tax | E2: Any change to posting logic or document flow | F2: 46114
A3: S-02 | B3: Consent and contactability | C3: DOM-01 Customer | D3: Marketing, legal (veto) | E3: Any new consumer of consent data | F3: 46161
A4: S-03 | B4: Stock in transit | C4: DOM-06 Logistics | D4: DOM-07 Store operations | E4: Any change to the ownership transfer point | F4: 45968
A5: S-04 | B5: Supplier onboarding versus vendor risk | C5: DOM-03 Source to contract | D5: Legal, compliance | E5: Any new market or new risk category | F5: 46184
A6: S-05 | B6: Employee identity and access | C6: DOM-08 People ops | D6: DOM-10 Security | E6: Any change to joiner, mover or leaver flow | F6: 46077
A7: S-06 | B7: Price versus promotion precedence | C7: DOM-05 Pricing | D7: Marketing | E7: Any change to the precedence rules | F7: 46111
A43: Six to eight entries. Do not redraw boundaries until the arguments stop - name the seam and give it a rule instead.

Sheet Landscape
A1: Link ID | B1: Type | C1: Dom ID | D1: App ID | E1: App / related name | F1: Object | G1: Interface | H1: Component | I1: Market | J1: Owner
A2: N-001 | B2: Domain to application | C2: DOM-03 | D2: APP-002 | E2: Core ERP | J2: IT operations
A3: N-002 | B3: Domain to application | C3: DOM-03 | D3: APP-044 | E3: Procurement portal | J3: Procurement IT
A4: N-003 | B4: Domain to application | C4: DOM-03 | D4: APP-118 | E4: Market D supplier register | I4: Market D | J4: Market D IT
A5: N-004 | B5: Domain to application | C5: DOM-03 | D5: APP-101 | E5: Contract system | J5: Legal IT
A6: N-005 | B6: Domain to application | C6: DOM-03 | D6: APP-131 | E6: Supplier onboarding service | J6: Integration team
A7: N-006 | B7: Domain to application | C7: DOM-03 | D7: APP-077 | E7: Data platform | J7: Data platform
A8: N-007 | B8: Application to object | C8: DOM-03 | D8: APP-002 | E8: Core ERP | F8: Supplier | J8: Procurement ops
A9: N-008 | B9: Application to object | C9: DOM-03 | D9: APP-101 | E9: Contract system | F9: Contract | J9: Legal ops
A10: N-009 | B10: Application to object | C10: DOM-03 | D10: APP-002 | E10: Core ERP | F10: Cost centre | J10: Controlling
A11: N-010 | B11: Application to interface | C11: DOM-03 | D11: APP-002 | E11: Core ERP | G11: INT-001 | J11: Integration team
A12: N-011 | B12: Application to interface | C12: DOM-03 | D12: APP-002 | E12: Core ERP | G12: INT-005 | J12: Integration team
A13: N-012 | B13: Application to interface | C13: DOM-03 | D13: APP-044 | E13: Procurement portal | G13: INT-012 | J13: Procurement IT
A14: N-013 | B14: Application to interface | C14: DOM-03 | D14: APP-118 | E14: Market D register | G14: INT-019 | I14: Market D | J14: Market D IT
A15: N-014 | B15: Application to interface | C15: DOM-03 | D15: APP-101 | E15: Contract system | G15: INT-023 | J15: Legal IT
A16: N-015 | B16: Application to interface | C16: DOM-03 | D16: APP-131 | E16: Onboarding service | G16: INT-031 | J16: Integration team
A17: N-016 | B17: Application to interface | C17: DOM-03 | D17: APP-131 | E17: Onboarding service | G17: INT-032 | J17: Integration team
A18: N-017 | B18: Application to interface | C18: DOM-03 | D18: APP-077 | E18: Data platform | G18: INT-040 | J18: Data platform
A19: N-018 | B19: Application to interface | C19: DOM-03 | D19: APP-002 | E19: Core ERP | G19: INT-041 | J19: Integration team
A20: N-019 | B20: Application to interface | C20: DOM-03 | D20: APP-002 | E20: Core ERP | G20: INT-044 | J20: Integration team
A21: N-020 | B21: Application to interface | C21: DOM-03 | D21: APP-044 | E21: Procurement portal | G21: INT-047 | J21: Procurement IT
A22: N-022 | B22: Application to component | C22: DOM-03 | D22: APP-002 | E22: Core ERP | H22: ITC-009 | I22: EU | J22: IT operations
A23: N-023 | B23: Application to component | C23: DOM-03 | D23: APP-118 | E23: Market D register | H23: ITC-041 | I23: Market D | J23: Market D IT
A24: N-024 | B24: Application to market | C24: DOM-03 | D24: APP-002 | E24: Core ERP | I24: Market A | J24: Market A IT
A25: N-025 | B25: Application to market | C25: DOM-03 | D25: APP-002 | E25: Core ERP | I25: Market B | J25: Market B IT
A26: N-026 | B26: Application to market | C26: DOM-03 | D26: APP-118 | E26: Market D register | I26: Market D | J26: Market D IT
A27: N-027 | B27: Application to market | C27: DOM-03 | D27: APP-131 | E27: Onboarding service | I27: Market E | J27: Market E IT
A28: N-028 | B28: Domain to application | C28: DOM-01 | D28: APP-011 | E28: CRM | J28: Marketing IT
A29: N-029 | B29: Domain to application | C29: DOM-01 | D29: APP-023 | E29: Commerce platform | J29: Digital
A30: N-030 | B30: Application to object | C30: DOM-01 | D30: APP-011 | E30: CRM | F30: Customer | J30: CRM team
A31: N-031 | B31: Application to interface | C31: DOM-01 | D31: APP-011 | E31: CRM | G31: INT-060 | J31: CRM team
A32: N-032 | B32: Application to interface | C32: DOM-01 | D32: APP-023 | E32: Commerce platform | G32: INT-061 | J32: Digital
A33: N-033 | B33: Application to component | C33: DOM-01 | D33: APP-011 | E33: CRM | H33: ITC-014 | I33: EU | J33: IT operations
A34: N-034 | B34: Application to market | C34: DOM-01 | D34: APP-011 | E34: CRM | I34: Market A | J34: Market A IT
A35: N-035 | B35: Domain to application | C35: DOM-05 | D35: APP-002 | E35: Core ERP | J35: IT operations
A36: N-036 | B36: Domain to application | C36: DOM-05 | D36: APP-131 | E36: Pricing service | J36: Pricing IT
A37: N-037 | B37: Domain to application | C37: DOM-05 | D37: APP-070 | E37: Promotion tool | J37: Marketing IT
A38: N-038 | B38: Domain to application | C38: DOM-05 | D38: APP-023 | E38: Commerce platform | J38: Digital
A39: N-039 | B39: Application to object | C39: DOM-05 | D39: APP-002 | E39: Core ERP | F39: Price | J39: Pricing
A40: N-040 | B40: Application to object | C40: DOM-05 | D40: APP-070 | E40: Promotion tool | F40: Promotion | J40: Marketing
...

Sheet Projects
A1: Prj ID | B1: Name | C1: Intake date | D1: Primary domain | E1: Domains touched | F1: Route | G1: Stage | H1: Reviewer | I1: Address assigned | J1: Days to address | K1: On time? | L1: Apps | M1: Objects | N1: Interfaces | O1: Components | P1: Markets | Q1: Constraints | R1: Over ceiling?
A2: PRJ-0418 | B2: Supplier onboarding for market D | C2: 46146 | D2: DOM-03 | E2: DOM-09, legal | F2: Extend what exists | G2: Definition | H2: Named | I2: 46148 | J2: =IF(OR(C2="",I2=""),0,I2-C2) | K2: =IF(A2="","",IF(J2<=Settings!$B$5,"yes","LATE")) | L2: =IF(A2="","",COUNTIFS(Landscape!$C$2:$C$601,$D2,Landscape!$B$2:$B$601,"Domain to application")) | M2: =IF(A2="","",COUNTIFS(Landscape!$C$2:$C$601,$D2,Landscape!$B$2:$B$601,"Application to object")) | N2: =IF(A2="","",COUNTIFS(Landscape!$C$2:$C$601,$D2,Landscape!$B$2:$B$601,"Application to interface")) | O2: =IF(A2="","",COUNTIFS(Landscape!$C$2:$C$601,$D2,Landscape!$B$2:$B$601,"Application to component")) | P2: =IF(A2="","",COUNTIFS(Landscape!$C$2:$C$601,$D2,Landscape!$B$2:$B$601,"Application to market")) | Q2: =IF(A2="","",COUNTIF(Constraints!$B$2:$B$201,$A2)) | R2: =IF(A2="","",IF(Q2>Settings!$B$4,"OVER","ok"))
A3: PRJ-0421 | B3: Consent capture in the loyalty app | C3: 46153 | D3: DOM-01 | E3: Marketing | F3: Build | G3: Execution | H3: Named | I3: 46154 | J3: =IF(OR(C3="",I3=""),0,I3-C3) | K3: =IF(A3="","",IF(J3<=Settings!$B$5,"yes","LATE")) | L3: =IF(A3="","",COUNTIFS(Landscape!$C$2:$C$601,$D3,Landscape!$B$2:$B$601,"Domain to application")) | M3: =IF(A3="","",COUNTIFS(Landscape!$C$2:$C$601,$D3,Landscape!$B$2:$B$601,"Application to object")) | N3: =IF(A3="","",COUNTIFS(Landscape!$C$2:$C$601,$D3,Landscape!$B$2:$B$601,"Application to interface")) | O3: =IF(A3="","",COUNTIFS(Landscape!$C$2:$C$601,$D3,Landscape!$B$2:$B$601,"Application to component")) | P3: =IF(A3="","",COUNTIFS(Landscape!$C$2:$C$601,$D3,Landscape!$B$2:$B$601,"Application to market")) | Q3: =IF(A3="","",COUNTIF(Constraints!$B$2:$B$201,$A3)) | R3: =IF(A3="","",IF(Q3>Settings!$B$4,"OVER","ok"))
A4: PRJ-0426 | B4: Replace the market D warehouse system | C4: 46168 | D4: DOM-06 | E4: DOM-07 | F4: Buy | G4: Funding decision | H4: Named | I4: 46170 | J4: =IF(OR(C4="",I4=""),0,I4-C4) | K4: =IF(A4="","",IF(J4<=Settings!$B$5,"yes","LATE")) | L4: =IF(A4="","",COUNTIFS(Landscape!$C$2:$C$601,$D4,Landscape!$B$2:$B$601,"Domain to application")) | M4: =IF(A4="","",COUNTIFS(Landscape!$C$2:$C$601,$D4,Landscape!$B$2:$B$601,"Application to object")) | N4: =IF(A4="","",COUNTIFS(Landscape!$C$2:$C$601,$D4,Landscape!$B$2:$B$601,"Application to interface")) | O4: =IF(A4="","",COUNTIFS(Landscape!$C$2:$C$601,$D4,Landscape!$B$2:$B$601,"Application to component")) | P4: =IF(A4="","",COUNTIFS(Landscape!$C$2:$C$601,$D4,Landscape!$B$2:$B$601,"Application to market")) | Q4: =IF(A4="","",COUNTIF(Constraints!$B$2:$B$201,$A4)) | R4: =IF(A4="","",IF(Q4>Settings!$B$4,"OVER","ok"))
A5: PRJ-0430 | B5: Pricing service phase two | C5: 46181 | D5: DOM-05 | E5: DOM-04 | F5: Build | G5: Definition | H5: Named | I5: 46182 | J5: =IF(OR(C5="",I5=""),0,I5-C5) | K5: =IF(A5="","",IF(J5<=Settings!$B$5,"yes","LATE")) | L5: =IF(A5="","",COUNTIFS(Landscape!$C$2:$C$601,$D5,Landscape!$B$2:$B$601,"Domain to application")) | M5: =IF(A5="","",COUNTIFS(Landscape!$C$2:$C$601,$D5,Landscape!$B$2:$B$601,"Application to object")) | N5: =IF(A5="","",COUNTIFS(Landscape!$C$2:$C$601,$D5,Landscape!$B$2:$B$601,"Application to interface")) | O5: =IF(A5="","",COUNTIFS(Landscape!$C$2:$C$601,$D5,Landscape!$B$2:$B$601,"Application to component")) | P5: =IF(A5="","",COUNTIFS(Landscape!$C$2:$C$601,$D5,Landscape!$B$2:$B$601,"Application to market")) | Q5: =IF(A5="","",COUNTIF(Constraints!$B$2:$B$201,$A5)) | R5: =IF(A5="","",IF(Q5>Settings!$B$4,"OVER","ok"))
A6: PRJ-0433 | B6: Contract repository migration | C6: 46188 | D6: DOM-03 | E6: DOM-09 | F6: Buy | G6: Intake | H6: Named | I6: 46195 | J6: =IF(OR(C6="",I6=""),0,I6-C6) | K6: =IF(A6="","",IF(J6<=Settings!$B$5,"yes","LATE")) | L6: =IF(A6="","",COUNTIFS(Landscape!$C$2:$C$601,$D6,Landscape!$B$2:$B$601,"Domain to application")) | M6: =IF(A6="","",COUNTIFS(Landscape!$C$2:$C$601,$D6,Landscape!$B$2:$B$601,"Application to object")) | N6: =IF(A6="","",COUNTIFS(Landscape!$C$2:$C$601,$D6,Landscape!$B$2:$B$601,"Application to interface")) | O6: =IF(A6="","",COUNTIFS(Landscape!$C$2:$C$601,$D6,Landscape!$B$2:$B$601,"Application to component")) | P6: =IF(A6="","",COUNTIFS(Landscape!$C$2:$C$601,$D6,Landscape!$B$2:$B$601,"Application to market")) | Q6: =IF(A6="","",COUNTIF(Constraints!$B$2:$B$201,$A6)) | R6: =IF(A6="","",IF(Q6>Settings!$B$4,"OVER","ok"))
J7: =IF(OR(C7="",I7=""),0,I7-C7) | K7: =IF(A7="","",IF(J7<=Settings!$B$5,"yes","LATE")) | L7: =IF(A7="","",COUNTIFS(Landscape!$C$2:$C$601,$D7,Landscape!$B$2:$B$601,"Domain to application")) | M7: =IF(A7="","",COUNTIFS(Landscape!$C$2:$C$601,$D7,Landscape!$B$2:$B$601,"Application to object")) | N7: =IF(A7="","",COUNTIFS(Landscape!$C$2:$C$601,$D7,Landscape!$B$2:$B$601,"Application to interface")) | O7: =IF(A7="","",COUNTIFS(Landscape!$C$2:$C$601,$D7,Landscape!$B$2:$B$601,"Application to component")) | P7: =IF(A7="","",COUNTIFS(Landscape!$C$2:$C$601,$D7,Landscape!$B$2:$B$601,"Application to market")) | Q7: =IF(A7="","",COUNTIF(Constraints!$B$2:$B$201,$A7)) | R7: =IF(A7="","",IF(Q7>Settings!$B$4,"OVER","ok"))
J8: =IF(OR(C8="",I8=""),0,I8-C8) | K8: =IF(A8="","",IF(J8<=Settings!$B$5,"yes","LATE")) | L8: =IF(A8="","",COUNTIFS(Landscape!$C$2:$C$601,$D8,Landscape!$B$2:$B$601,"Domain to application")) | M8: =IF(A8="","",COUNTIFS(Landscape!$C$2:$C$601,$D8,Landscape!$B$2:$B$601,"Application to object")) | N8: =IF(A8="","",COUNTIFS(Landscape!$C$2:$C$601,$D8,Landscape!$B$2:$B$601,"Application to interface")) | O8: =IF(A8="","",COUNTIFS(Landscape!$C$2:$C$601,$D8,Landscape!$B$2:$B$601,"Application to component")) | P8: =IF(A8="","",COUNTIFS(Landscape!$C$2:$C$601,$D8,Landscape!$B$2:$B$601,"Application to market")) | Q8: =IF(A8="","",COUNTIF(Constraints!$B$2:$B$201,$A8)) | R8: =IF(A8="","",IF(Q8>Settings!$B$4,"OVER","ok"))
J9: =IF(OR(C9="",I9=""),0,I9-C9) | K9: =IF(A9="","",IF(J9<=Settings!$B$5,"yes","LATE")) | L9: =IF(A9="","",COUNTIFS(Landscape!$C$2:$C$601,$D9,Landscape!$B$2:$B$601,"Domain to application")) | M9: =IF(A9="","",COUNTIFS(Landscape!$C$2:$C$601,$D9,Landscape!$B$2:$B$601,"Application to object")) | N9: =IF(A9="","",COUNTIFS(Landscape!$C$2:$C$601,$D9,Landscape!$B$2:$B$601,"Application to interface")) | O9: =IF(A9="","",COUNTIFS(Landscape!$C$2:$C$601,$D9,Landscape!$B$2:$B$601,"Application to component")) | P9: =IF(A9="","",COUNTIFS(Landscape!$C$2:$C$601,$D9,Landscape!$B$2:$B$601,"Application to market")) | Q9: =IF(A9="","",COUNTIF(Constraints!$B$2:$B$201,$A9)) | R9: =IF(A9="","",IF(Q9>Settings!$B$4,"OVER","ok"))
J10: =IF(OR(C10="",I10=""),0,I10-C10) | K10: =IF(A10="","",IF(J10<=Settings!$B$5,"yes","LATE")) | L10: =IF(A10="","",COUNTIFS(Landscape!$C$2:$C$601,$D10,Landscape!$B$2:$B$601,"Domain to application")) | M10: =IF(A10="","",COUNTIFS(Landscape!$C$2:$C$601,$D10,Landscape!$B$2:$B$601,"Application to object")) | N10: =IF(A10="","",COUNTIFS(Landscape!$C$2:$C$601,$D10,Landscape!$B$2:$B$601,"Application to interface")) | O10: =IF(A10="","",COUNTIFS(Landscape!$C$2:$C$601,$D10,Landscape!$B$2:$B$601,"Application to component")) | P10: =IF(A10="","",COUNTIFS(Landscape!$C$2:$C$601,$D10,Landscape!$B$2:$B$601,"Application to market")) | Q10: =IF(A10="","",COUNTIF(Constraints!$B$2:$B$201,$A10)) | R10: =IF(A10="","",IF(Q10>Settings!$B$4,"OVER","ok"))
J11: =IF(OR(C11="",I11=""),0,I11-C11) | K11: =IF(A11="","",IF(J11<=Settings!$B$5,"yes","LATE")) | L11: =IF(A11="","",COUNTIFS(Landscape!$C$2:$C$601,$D11,Landscape!$B$2:$B$601,"Domain to application")) | M11: =IF(A11="","",COUNTIFS(Landscape!$C$2:$C$601,$D11,Landscape!$B$2:$B$601,"Application to object")) | N11: =IF(A11="","",COUNTIFS(Landscape!$C$2:$C$601,$D11,Landscape!$B$2:$B$601,"Application to interface")) | O11: =IF(A11="","",COUNTIFS(Landscape!$C$2:$C$601,$D11,Landscape!$B$2:$B$601,"Application to component")) | P11: =IF(A11="","",COUNTIFS(Landscape!$C$2:$C$601,$D11,Landscape!$B$2:$B$601,"Application to market")) | Q11: =IF(A11="","",COUNTIF(Constraints!$B$2:$B$201,$A11)) | R11: =IF(A11="","",IF(Q11>Settings!$B$4,"OVER","ok"))
J12: =IF(OR(C12="",I12=""),0,I12-C12) | K12: =IF(A12="","",IF(J12<=Settings!$B$5,"yes","LATE")) | L12: =IF(A12="","",COUNTIFS(Landscape!$C$2:$C$601,$D12,Landscape!$B$2:$B$601,"Domain to application")) | M12: =IF(A12="","",COUNTIFS(Landscape!$C$2:$C$601,$D12,Landscape!$B$2:$B$601,"Application to object")) | N12: =IF(A12="","",COUNTIFS(Landscape!$C$2:$C$601,$D12,Landscape!$B$2:$B$601,"Application to interface")) | O12: =IF(A12="","",COUNTIFS(Landscape!$C$2:$C$601,$D12,Landscape!$B$2:$B$601,"Application to component")) | P12: =IF(A12="","",COUNTIFS(Landscape!$C$2:$C$601,$D12,Landscape!$B$2:$B$601,"Application to market")) | Q12: =IF(A12="","",COUNTIF(Constraints!$B$2:$B$201,$A12)) | R12: =IF(A12="","",IF(Q12>Settings!$B$4,"OVER","ok"))
J13: =IF(OR(C13="",I13=""),0,I13-C13) | K13: =IF(A13="","",IF(J13<=Settings!$B$5,"yes","LATE")) | L13: =IF(A13="","",COUNTIFS(Landscape!$C$2:$C$601,$D13,Landscape!$B$2:$B$601,"Domain to application")) | M13: =IF(A13="","",COUNTIFS(Landscape!$C$2:$C$601,$D13,Landscape!$B$2:$B$601,"Application to object")) | N13: =IF(A13="","",COUNTIFS(Landscape!$C$2:$C$601,$D13,Landscape!$B$2:$B$601,"Application to interface")) | O13: =IF(A13="","",COUNTIFS(Landscape!$C$2:$C$601,$D13,Landscape!$B$2:$B$601,"Application to component")) | P13: =IF(A13="","",COUNTIFS(Landscape!$C$2:$C$601,$D13,Landscape!$B$2:$B$601,"Application to market")) | Q13: =IF(A13="","",COUNTIF(Constraints!$B$2:$B$201,$A13)) | R13: =IF(A13="","",IF(Q13>Settings!$B$4,"OVER","ok"))
J14: =IF(OR(C14="",I14=""),0,I14-C14) | K14: =IF(A14="","",IF(J14<=Settings!$B$5,"yes","LATE")) | L14: =IF(A14="","",COUNTIFS(Landscape!$C$2:$C$601,$D14,Landscape!$B$2:$B$601,"Domain to application")) | M14: =IF(A14="","",COUNTIFS(Landscape!$C$2:$C$601,$D14,Landscape!$B$2:$B$601,"Application to object")) | N14: =IF(A14="","",COUNTIFS(Landscape!$C$2:$C$601,$D14,Landscape!$B$2:$B$601,"Application to interface")) | O14: =IF(A14="","",COUNTIFS(Landscape!$C$2:$C$601,$D14,Landscape!$B$2:$B$601,"Application to component")) | P14: =IF(A14="","",COUNTIFS(Landscape!$C$2:$C$601,$D14,Landscape!$B$2:$B$601,"Application to market")) | Q14: =IF(A14="","",COUNTIF(Constraints!$B$2:$B$201,$A14)) | R14: =IF(A14="","",IF(Q14>Settings!$B$4,"OVER","ok"))
J15: =IF(OR(C15="",I15=""),0,I15-C15) | K15: =IF(A15="","",IF(J15<=Settings!$B$5,"yes","LATE")) | L15: =IF(A15="","",COUNTIFS(Landscape!$C$2:$C$601,$D15,Landscape!$B$2:$B$601,"Domain to application")) | M15: =IF(A15="","",COUNTIFS(Landscape!$C$2:$C$601,$D15,Landscape!$B$2:$B$601,"Application to object")) | N15: =IF(A15="","",COUNTIFS(Landscape!$C$2:$C$601,$D15,Landscape!$B$2:$B$601,"Application to interface")) | O15: =IF(A15="","",COUNTIFS(Landscape!$C$2:$C$601,$D15,Landscape!$B$2:$B$601,"Application to component")) | P15: =IF(A15="","",COUNTIFS(Landscape!$C$2:$C$601,$D15,Landscape!$B$2:$B$601,"Application to market")) | Q15: =IF(A15="","",COUNTIF(Constraints!$B$2:$B$201,$A15)) | R15: =IF(A15="","",IF(Q15>Settings!$B$4,"OVER","ok"))
J16: =IF(OR(C16="",I16=""),0,I16-C16) | K16: =IF(A16="","",IF(J16<=Settings!$B$5,"yes","LATE")) | L16: =IF(A16="","",COUNTIFS(Landscape!$C$2:$C$601,$D16,Landscape!$B$2:$B$601,"Domain to application")) | M16: =IF(A16="","",COUNTIFS(Landscape!$C$2:$C$601,$D16,Landscape!$B$2:$B$601,"Application to object")) | N16: =IF(A16="","",COUNTIFS(Landscape!$C$2:$C$601,$D16,Landscape!$B$2:$B$601,"Application to interface")) | O16: =IF(A16="","",COUNTIFS(Landscape!$C$2:$C$601,$D16,Landscape!$B$2:$B$601,"Application to component")) | P16: =IF(A16="","",COUNTIFS(Landscape!$C$2:$C$601,$D16,Landscape!$B$2:$B$601,"Application to market")) | Q16: =IF(A16="","",COUNTIF(Constraints!$B$2:$B$201,$A16)) | R16: =IF(A16="","",IF(Q16>Settings!$B$4,"OVER","ok"))
J17: =IF(OR(C17="",I17=""),0,I17-C17) | K17: =IF(A17="","",IF(J17<=Settings!$B$5,"yes","LATE")) | L17: =IF(A17="","",COUNTIFS(Landscape!$C$2:$C$601,$D17,Landscape!$B$2:$B$601,"Domain to application")) | M17: =IF(A17="","",COUNTIFS(Landscape!$C$2:$C$601,$D17,Landscape!$B$2:$B$601,"Application to object")) | N17: =IF(A17="","",COUNTIFS(Landscape!$C$2:$C$601,$D17,Landscape!$B$2:$B$601,"Application to interface")) | O17: =IF(A17="","",COUNTIFS(Landscape!$C$2:$C$601,$D17,Landscape!$B$2:$B$601,"Application to component")) | P17: =IF(A17="","",COUNTIFS(Landscape!$C$2:$C$601,$D17,Landscape!$B$2:$B$601,"Application to market")) | Q17: =IF(A17="","",COUNTIF(Constraints!$B$2:$B$201,$A17)) | R17: =IF(A17="","",IF(Q17>Settings!$B$4,"OVER","ok"))
J18: =IF(OR(C18="",I18=""),0,I18-C18) | K18: =IF(A18="","",IF(J18<=Settings!$B$5,"yes","LATE")) | L18: =IF(A18="","",COUNTIFS(Landscape!$C$2:$C$601,$D18,Landscape!$B$2:$B$601,"Domain to application")) | M18: =IF(A18="","",COUNTIFS(Landscape!$C$2:$C$601,$D18,Landscape!$B$2:$B$601,"Application to object")) | N18: =IF(A18="","",COUNTIFS(Landscape!$C$2:$C$601,$D18,Landscape!$B$2:$B$601,"Application to interface")) | O18: =IF(A18="","",COUNTIFS(Landscape!$C$2:$C$601,$D18,Landscape!$B$2:$B$601,"Application to component")) | P18: =IF(A18="","",COUNTIFS(Landscape!$C$2:$C$601,$D18,Landscape!$B$2:$B$601,"Application to market")) | Q18: =IF(A18="","",COUNTIF(Constraints!$B$2:$B$201,$A18)) | R18: =IF(A18="","",IF(Q18>Settings!$B$4,"OVER","ok"))
... J121: =IF(OR(C121="",I121=""),0,I121-C121) | K121: =IF(A121="","",IF(J121<=Settings!$B$5,"yes","LATE")) | L121: =IF(A121="","",COUNTIFS(Landscape!$C$2:$C$601,$D121,Landscape!$B$2:$B$601,"Domain to application")) | M121: =IF(A121="","",COUNTIFS(Landscape!$C$2:$C$601,$D121,Landscape!$B$2:$B$601,"Application to object")) | N121: =IF(A121="","",COUNTIFS(Landscape!$C$2:$C$601,$D121,Landscape!$B$2:$B$601,"Application to interface")) | O121: =IF(A121="","",COUNTIFS(Landscape!$C$2:$C$601,$D121,Landscape!$B$2:$B$601,"Application to component")) | P121: =IF(A121="","",COUNTIFS(Landscape!$C$2:$C$601,$D121,Landscape!$B$2:$B$601,"Application to market")) | Q121: =IF(A121="","",COUNTIF(Constraints!$B$2:$B$201,$A121)) | R121: =IF(A121="","",IF(Q121>Settings!$B$4,"OVER","ok"))
A123: Columns L to P are the cascade: counts only. The names come from filtering Landscape by the primary domain - and the names are what the impact list is for.

Sheet Constraints
A1: Con ID | B1: Prj ID | C1: Statement | D1: Reason - for this organization | E1: Source type | F1: Source ref | G1: Test - answerable alone in five minutes | H1: Owner | I1: Expiry | J1: Days to expiry | K1: Closure status
A2: CON-01 | B2: PRJ-0418 | C2: Every interface to the core uses a released API or event | D2: Two direct table reads built in 2022 broke the last upgrade and cost a weekend of unplanned work | E2: Integration standard | F2: Rule 1 | G2: Name the API or event for each integration point in your design. If you cannot name one, raise it now | H2: Named architect | I2: 46568 | J2: =IF(I2="","",I2-Settings!$B$2) | K2: Open
A3: CON-02 | B3: PRJ-0418 | C3: Supplier remains mastered by the core; this solution reads and proposes, it does not write | D3: Three of last year's four data incidents came from two systems believing they owned one object | E3: Principle | F3: P-01 | G3: List every write in your design and name the object and its master. Any write to supplier is a deviation | H3: Named architect | J3: =IF(I3="","",I3-Settings!$B$2) | K3: Open
A4: CON-03 | B4: PRJ-0418 | C4: Market D data classified as personal stays in-country | D4: Statutory. Named in the residency register for market D | E4: Law or regulation | F4: Residency register | G4: Name the component and region for every store of personal data in your design | H4: Compliance lead | J4: =IF(I4="","",I4-Settings!$B$2) | K4: Met
A5: CON-04 | B5: PRJ-0418 | C5: Use the existing onboarding workflow pattern rather than a new one | D5: The same workflow has been built three times in two years | E5: Pattern | F5: PAT-07 | G5: Point at the pattern reference in your design, or state which of its constraints does not hold here | H5: Named architect | I5: 46568 | J5: =IF(I5="","",I5-Settings!$B$2) | K5: Open
A6: CON-05 | B6: PRJ-0418 | C6: Close exception EXC-09 rather than extending it | D6: It was registered as temporary in 2024 and this project is the reason it can end | E6: Board decision | F6: ADR-071 | G6: Confirm at closure that EXC-09 is closed, not renewed | H6: Named architect | I6: 46387 | J6: =IF(I6="","",I6-Settings!$B$2) | K6: Open
A7: CON-06 | B7: PRJ-0418 | C7: No new local supplier store in any market | D7: Domain target direction; two registers already exist under contract and no more are wanted | E7: Principle | F7: P-03 | G7: Does this design create a persistent supplier record anywhere outside the core or the two registered stores? | H7: Domain architect | J7: =IF(I7="","",I7-Settings!$B$2) | K7: Open
A8: CON-07 | B8: PRJ-0426 | C8: The product operates against externally mastered material data | D8: Buying a system that insists on mastering material would reopen a settled decision | E8: Principle | F8: P-01 | G8: Demonstrated live against our test instance, not asserted in a questionnaire | H8: Named architect | J8: =IF(I8="","",I8-Settings!$B$2) | K8: Open
A9: CON-08 | B9: PRJ-0426 | C9: Data for this market remains in-country in the vendor's hosting | D9: Statutory | E9: Law or regulation | F9: Residency register | G9: Named region in the contract, not in the proposal | H9: Compliance lead | J9: =IF(I9="","",I9-Settings!$B$2) | K9: Open
A10: CON-09 | B10: PRJ-0426 | C10: Exit provision: full data extract in a documented format within 30 days of termination | D10: A previous vendor exit took eleven months and cost more than a year of licence fees | E10: Board decision | F10: ADR-055 | G10: Clause present in the signed contract | H10: Procurement | J10: =IF(I10="","",I10-Settings!$B$2) | K10: Open
A11: CON-10 | B11: PRJ-0430 | C11: Price mastership moves to the pricing service with a dual-write window that expires | D11: A window with no written end date once ran for two years | E11: Board decision | F11: ADR-092 | G11: Exception registered with an expiry date before cutover | H11: Named architect | I11: 46380 | J11: =IF(I11="","",I11-Settings!$B$2) | K11: Open
A12: CON-11 | B12: PRJ-0421 | C12: Consent is read from the customer master, never captured a second time | D12: Two consent records for one person is a regulatory finding waiting to happen | E12: Principle | F12: P-01 | G12: Name the source of every consent value shown or stored | H12: Named architect | J12: =IF(I12="","",I12-Settings!$B$2) | K12: Deviated - exception registered
J13: =IF(I13="","",I13-Settings!$B$2)
J14: =IF(I14="","",I14-Settings!$B$2)
J15: =IF(I15="","",I15-Settings!$B$2)
J16: =IF(I16="","",I16-Settings!$B$2)
J17: =IF(I17="","",I17-Settings!$B$2)
J18: =IF(I18="","",I18-Settings!$B$2)
J19: =IF(I19="","",I19-Settings!$B$2)
J20: =IF(I20="","",I20-Settings!$B$2)
J21: =IF(I21="","",I21-Settings!$B$2)
J22: =IF(I22="","",I22-Settings!$B$2)
J23: =IF(I23="","",I23-Settings!$B$2)
J24: =IF(I24="","",I24-Settings!$B$2)
... J201: =IF(I201="","",I201-Settings!$B$2)

Sheet Vendor scoring
A1: Architecture criteria for vendor selection
A2: Mandatory criteria first. A mandatory criterion removes a vendor rather than costing points, which makes it worth more than any weight. Anchors written before anyone sees a proposal.
A4: Ref | B4: Criterion | C4: Category | D4: Weight | E4: Anchor: what a 5 looks like | F4: Anchor: what a 2 looks like | G4: Vendor A | H4: Vendor B
A5: M-1 | B5: Operates against externally mastered core data without maintaining its own authoritative copy | C5: Mandatory | E5: Demonstrated live against our test instance | F5: - | G5: PASS | H5: FAIL
A6: M-2 | B6: Data for named markets can be hosted in-country, contractually | C6: Mandatory | E6: Named region in the draft contract | F6: - | G6: PASS | H6: PASS
A7: M-3 | B7: Full data extract in a documented format within 30 days of termination | C7: Mandatory | E7: Clause offered before negotiation | F7: - | G7: PASS | H7: PASS
A8: W-1 | B8: Released, versioned APIs covering the objects we exchange | C8: Weighted | D8: 0.3 | E8: Public documentation, versioning policy, deprecation notice period stated | F8: Bespoke endpoints built per customer, no versioning | G8: 4 | H8: 3
A9: W-2 | B9: Event publication for the objects we consume | C9: Weighted | D9: 0.2 | E9: Native event stream with replay from a point in time | F9: Polling only | G9: 5 | H9: 2
A10: W-3 | B10: Configuration depth before code is required | C10: Weighted | D10: 0.2 | E10: Our three known variants configurable, shown live | F10: Two of three need vendor development | G10: 4 | H10: 4
A11: W-4 | B11: Identity integration with our standard | C11: Weighted | D11: 0.15 | E11: Standards-based, self-service, demonstrated | F11: Supported via a professional services engagement | G11: 3 | H11: 5
A12: W-5 | B12: Upgrade cadence and customer control over timing | C12: Weighted | D12: 0.15 | E12: Published cadence, customer window, rehearsal environment | F12: Forced upgrades with two weeks' notice | G12: 4 | H12: 3
A27: Result
A28: Mandatory criteria failed | G28: =COUNTIFS($C$5:$C$24,"Mandatory",G$5:G$24,"FAIL") | H28: =COUNTIFS($C$5:$C$24,"Mandatory",H$5:H$24,"FAIL")
A29: Weighted architecture score (0 to 5) | G29: =IFERROR(SUMPRODUCT(($C$5:$C$24="Weighted")*$D$5:$D$24*IF(ISNUMBER(G$5:G$24),G$5:G$24,0))/SUMIF($C$5:$C$24,"Weighted",$D$5:$D$24),"") | H29: =IFERROR(SUMPRODUCT(($C$5:$C$24="Weighted")*$D$5:$D$24*IF(ISNUMBER(H$5:H$24),H$5:H$24,0))/SUMIF($C$5:$C$24,"Weighted",$D$5:$D$24),"")
A30: Contribution to the total evaluation | G30: =IFERROR(G29/5*Settings!$B$6,"") | H30: =IFERROR(H29/5*Settings!$B$6,"")
A31: Verdict | G31: =IF(G28>0,"EXCLUDED - mandatory criterion failed","In scope") | H31: =IF(H28>0,"EXCLUDED - mandatory criterion failed","In scope")
A33: Evidence rules, per criterion: a live demonstration on our test instance, published API documentation, a reference call with a customer of similar shape, or a written contractual commitment. A yes on a questionnaire is not evidence.
A34: Architecture share of the total evaluation is on the Settings sheet. At ten per cent it is a rounding error with a seat at the table. Twenty-five to thirty is where it becomes real - and one extra mandatory criterion is worth more than five points of weight.
