Workbook

Sheet Read me
A1: Object model workbook
A2: The data model in one file: the object register, the attributes, one flat link table carrying all four joins, attestation, exceptions with expiry, and a derived-views sheet that computes the answers you actually get asked.
A4: Why one flat link table
A5: Four joins - object to capability, application, IT component, and interface - live in a single Links sheet with a Type column. One table is easier to maintain than four, filters like four, and imports into a portfolio tool without reshaping. The role on each link (master, reference, consumer) is the entire information content; a link without a role tells you only that two things are related, which you already suspected.
A7: The sheets
A8: Settings - as-at date, attestation window, and the object count ceiling. Change these first.
A9: Objects - one row per domain object. Master, owner, steward, capability, definition, boundary, classification, residency, attestation.
A10: Attributes - the arguable subset only, with jurisdiction scoping. Eight to fifteen per object, not the schema.
A11: Links - the four joins. Type, from, to, role, and a note.
A12: Exceptions - registered deviations with expiry, including dual-write windows.
A13: Derived views - the contradiction report, orphan capabilities, residency answer, change impact, and the three report lines.
A15: How to run it
... A27: Companion article: mehdibamou.com/publications/data-strategy-object-model - free to use and adapt

Sheet Settings
A1: Setting | B1: Value | C1: Note
A2: As-at date | B2: 46203 | C2: Month end. Drives attestation ages and expiry countdowns
A3: Attestation window (days) | B3: 120 | C3: Beyond this an object is stale and produces a finding
A4: Object count ceiling | B4: 40 | C4: A soft limit that should be argued about, not silently exceeded
A5: Attributes per object ceiling | B5: 15 | C5: The arguable subset only - never the schema
A6: Warn before expiry (days) | B6: 60 | C6: How early a reference copy or dual-write window shows as due

Sheet Lists
A1: Object to capability | B1: Master | C1: Proposed | D1: Public | E1: Group | F1: Open
A2: Object to application | B2: Reference | C2: Active | D2: Internal | E2: Jurisdiction-scoped | F2: Closed
A3: Object to IT component | B3: Consumer | C3: Contested | D3: Confidential | E3: Local | F3: Extended
A4: Object to interface | B4: Owns lifecycle | C4: Retired | D4: Personal data | F4: Expired
B5: Sits on
B6: Carried by

Sheet Objects
A1: Obj ID | B1: Name | C1: Aliases | D1: Definition | E1: What this is not | F1: Owning capability | G1: Business owner | H1: Data steward | I1: System of record | J1: Classification | K1: Residency | L1: Retention | M1: Status | N1: Last attested | O1: Days since attested | P1: Stale?
A2: OBJ-01 | B2: Customer | C2: Account (CRM), Debtor (finance), Shopper (commerce), Card holder (loyalty) | D2: A person or organization that has bought from us, or has consented to be contacted with a view to buying | E2: Not a prospect with no consent. Not a delivery recipient. Not a loyalty account | F2: Customer management | G2: Head of CRM | H2: Named steward | I2: CRM | J2: Personal data | K2: Markets B, E, G in-country | L2: Per jurisdiction | M2: Active | N2: 46160 | O2: =IF(N2="",0,Settings!$B$2-N2) | P2: =IF(A2="","",IF(N2="","never",IF(O2>Settings!$B$3,"STALE","ok")))
A3: OBJ-02 | B3: Material | C3: Article (commerce), SKU (planning), Produkt (market C) | D3: A thing we sell or consume, identified at the level we plan and price it | E3: Not a variant display grouping. Not a bill of materials | F3: Product management | G3: Head of master data | H3: Named steward | I3: Core ERP | J3: Internal | K3: None | L3: Indefinite | M3: Active | N3: 46175 | O3: =IF(N3="",0,Settings!$B$2-N3) | P3: =IF(A3="","",IF(N3="","never",IF(O3>Settings!$B$3,"STALE","ok")))
A4: OBJ-03 | B4: Employee | C4: Worker (HR), Mitarbeiter (market C), User (identity) | D4: A person under an employment or equivalent contract with a group entity | E4: Not a contractor without a group contract. Not a system account | F4: People operations | G4: HR operations lead | H4: Named steward | I4: HR system | J4: Personal data | K4: All markets in-country | L4: Per jurisdiction | M4: Active | N4: 46141 | O4: =IF(N4="",0,Settings!$B$2-N4) | P4: =IF(A4="","",IF(N4="","never",IF(O4>Settings!$B$3,"STALE","ok")))
A5: OBJ-04 | B5: Supplier | C5: Vendor (core, market A), Creditor (finance), Lieferant (market C), Partner (portal) | D5: A legal entity we can raise a purchase order against | E5: Not a manufacturer we buy through a distributor. Not a one-off payee. Not a carrier | F5: Source to contract | G5: Head of procurement ops | H5: Named steward | I5: Core ERP | J5: Internal | K5: Markets B, E in-country | L5: 10 years | M5: Active | N5: 46184 | O5: =IF(N5="",0,Settings!$B$2-N5) | P5: =IF(A5="","",IF(N5="","never",IF(O5>Settings!$B$3,"STALE","ok")))
A6: OBJ-05 | B6: Sales order | C6: Order (commerce), Auftrag (market C) | D6: A customer commitment to buy, at agreed terms, before fulfilment | E6: Not a quotation. Not a delivery | F6: Order management | G6: Head of order management | H6: Named steward | I6: Core ERP | J6: Internal | K6: None | L6: 10 years | M6: Active | N6: 46146 | O6: =IF(N6="",0,Settings!$B$2-N6) | P6: =IF(A6="","",IF(N6="","never",IF(O6>Settings!$B$3,"STALE","ok")))
A7: OBJ-06 | B7: Contract | C7: Agreement (legal), Rahmenvertrag (market C) | D7: A signed commercial agreement with an entity, with a term and obligations | E7: Not a purchase order. Not a statement of work under an existing agreement | F7: Source to contract | G7: Head of legal ops | H7: Named steward | I7: Contract system | J7: Confidential | K7: Market F in-country | L7: Term plus 10 years | M7: Active | N7: 46097 | O7: =IF(N7="",0,Settings!$B$2-N7) | P7: =IF(A7="","",IF(N7="","never",IF(O7>Settings!$B$3,"STALE","ok")))
A8: OBJ-07 | B8: Price | C8: Listenpreis (market C), List price (commerce) | D8: The amount we ask for a material in a market on a date, before customer-specific conditions | E8: Not a cost. Not a promotion. Not the invoiced amount | F8: Pricing | G8: Head of pricing | H8: Named steward | I8: Core ERP | J8: Internal | K8: None | L8: 5 years | M8: Contested | N8: 46182 | O8: =IF(N8="",0,Settings!$B$2-N8) | P8: =IF(A8="","",IF(N8="","never",IF(O8>Settings!$B$3,"STALE","ok")))
A9: OBJ-08 | B9: Cost centre | C9: Kostenstelle (market C), Department (HR) | D9: A unit of the organization against which cost is booked | E9: Not a legal entity. Not a team in the org chart | F9: Finance operations | G9: Head of controlling | H9: Named steward | I9: Core ERP | J9: Internal | K9: None | L9: Indefinite | M9: Active | N9: 46077 | O9: =IF(N9="",0,Settings!$B$2-N9) | P9: =IF(A9="","",IF(N9="","never",IF(O9>Settings!$B$3,"STALE","ok")))
A10: OBJ-09 | B10: Store | C10: Site, Filiale (market C), Location (logistics) | D10: A physical place where we trade with customers | E10: Not a warehouse. Not a legal entity | F10: Store operations | G10: Head of store ops | H10: Named steward | I10: Core ERP | J10: Internal | K10: None | L10: Indefinite | M10: Active | N10: 46188 | O10: =IF(N10="",0,Settings!$B$2-N10) | P10: =IF(A10="","",IF(N10="","never",IF(O10>Settings!$B$3,"STALE","ok")))
A11: OBJ-10 | B11: Promotion | C11: Aktion (market C), Campaign (marketing) | D11: A time-bounded change to price or terms, targeted at a segment or channel | E11: Not a price. Not a loyalty offer to one customer | F11: Marketing | G11: Head of trade marketing | H11: Named steward | I11: Promotion tool | J11: Internal | K11: None | L11: 3 years | M11: Active | N11: 45981 | O11: =IF(N11="",0,Settings!$B$2-N11) | P11: =IF(A11="","",IF(N11="","never",IF(O11>Settings!$B$3,"STALE","ok")))
O12: =IF(N12="",0,Settings!$B$2-N12) | P12: =IF(A12="","",IF(N12="","never",IF(O12>Settings!$B$3,"STALE","ok")))
O13: =IF(N13="",0,Settings!$B$2-N13) | P13: =IF(A13="","",IF(N13="","never",IF(O13>Settings!$B$3,"STALE","ok")))
O14: =IF(N14="",0,Settings!$B$2-N14) | P14: =IF(A14="","",IF(N14="","never",IF(O14>Settings!$B$3,"STALE","ok")))
O15: =IF(N15="",0,Settings!$B$2-N15) | P15: =IF(A15="","",IF(N15="","never",IF(O15>Settings!$B$3,"STALE","ok")))
O16: =IF(N16="",0,Settings!$B$2-N16) | P16: =IF(A16="","",IF(N16="","never",IF(O16>Settings!$B$3,"STALE","ok")))
O17: =IF(N17="",0,Settings!$B$2-N17) | P17: =IF(A17="","",IF(N17="","never",IF(O17>Settings!$B$3,"STALE","ok")))
O18: =IF(N18="",0,Settings!$B$2-N18) | P18: =IF(A18="","",IF(N18="","never",IF(O18>Settings!$B$3,"STALE","ok")))
O19: =IF(N19="",0,Settings!$B$2-N19) | P19: =IF(A19="","",IF(N19="","never",IF(O19>Settings!$B$3,"STALE","ok")))
O20: =IF(N20="",0,Settings!$B$2-N20) | P20: =IF(A20="","",IF(N20="","never",IF(O20>Settings!$B$3,"STALE","ok")))
O21: =IF(N21="",0,Settings!$B$2-N21) | P21: =IF(A21="","",IF(N21="","never",IF(O21>Settings!$B$3,"STALE","ok")))
O22: =IF(N22="",0,Settings!$B$2-N22) | P22: =IF(A22="","",IF(N22="","never",IF(O22>Settings!$B$3,"STALE","ok")))
O23: =IF(N23="",0,Settings!$B$2-N23) | P23: =IF(A23="","",IF(N23="","never",IF(O23>Settings!$B$3,"STALE","ok")))
... O61: =IF(N61="",0,Settings!$B$2-N61) | P61: =IF(A61="","",IF(N61="","never",IF(O61>Settings!$B$3,"STALE","ok")))

Sheet Attributes
A1: Obj ID | B1: Attribute | C1: Scope | D1: Jurisdictions | E1: Mandatory? | F1: The decision it feeds | G1: Quality rule | H1: Current value | I1: Note
A2: OBJ-04 | B2: Supplier number | C2: Group | E2: Yes | F2: Every match, migration and cross-reference | G2: Unique, non-blank | H2: 100%
A3: OBJ-04 | B3: Legal name | C3: Group | E3: Yes | F3: Whether two records are the same entity | G3: Non-blank | H3: 99.8%
A4: OBJ-04 | B4: Tax identifier | C4: Jurisdiction-scoped | D4: Markets A, B, C, E, F | E4: Yes | F4: Whether we may pay them, and statutory reporting | G4: Format valid per market | H4: 94% | I4: Format differs per market - one rule, five patterns
A5: OBJ-04 | B5: Statutory address | C5: Jurisdiction-scoped | D5: Markets B, E | E5: Yes | F5: Statutory reporting in two markets | G5: Non-blank where in scope | H5: 91%
A6: OBJ-04 | B6: Payment reporting flag | C6: Jurisdiction-scoped | D6: Market E | E6: No | F6: A statutory return in one market | G6: Set where in scope | H6: 88% | I6: Built once in the localization layer, not per market
A7: OBJ-04 | B7: Payment terms | C7: Group | E7: Yes | F7: Cash flow forecasting, and the invoice due date | G7: Within the approved set | H7: 97%
A8: OBJ-04 | B8: Blocked flag and reason | C8: Group | E8: Yes | F8: Whether a purchase order may be raised at all | G8: Reason present when blocked | H8: 93%
A9: OBJ-04 | B9: Category | C9: Group | E9: No | F9: Spend analysis and sourcing strategy | G9: In the taxonomy | H9: 82% | I9: Weakest attribute; the sourcing team is fixing it
A10: OBJ-01 | B10: Customer identifier | C10: Group | E10: Yes | F10: Every join across CRM, commerce and finance | G10: Unique | H10: 100%
A11: OBJ-01 | B11: Consent record | C11: Jurisdiction-scoped | D11: All | E11: Yes | F11: Whether we may contact them at all | G11: Present with a timestamp and basis | H11: 96% | I11: Legal basis differs by jurisdiction
A12: OBJ-01 | B12: Country of residence | C12: Group | E12: Yes | F12: Which residency and retention rules apply | G12: Non-blank, ISO code | H12: 99% | I12: This attribute is what makes the residency query answerable
A13: OBJ-07 | B13: Price value and currency | C13: Group | E13: Yes | F13: Everything downstream of pricing | G13: Non-blank, positive | H13: 100%
A14: OBJ-07 | B14: Valid from and to | C14: Group | E14: Yes | F14: Which price applies on a date | G14: No overlapping ranges | H14: 89% | I14: Overlaps are the most common pricing incident
A403: Column F is the argument you make when somebody proposes a fourteenth attribute. If it cannot be filled in, the attribute does not go on the sheet.

Sheet Links
A1: Link ID | B1: Type | C1: Obj ID | D1: Related ID | E1: Related name | F1: Role | G1: Region / market | H1: Expires | I1: Days to expiry | J1: Note
A2: L-001 | B2: Object to capability | C2: OBJ-04 | D2: CAP-031 | E2: Source to contract | F2: Owns lifecycle | I2: =IF(H2="","",H2-Settings!$B$2)
A3: L-002 | B3: Object to application | C3: OBJ-04 | D3: APP-002 | E3: Core ERP | F3: Master | I3: =IF(H3="","",H3-Settings!$B$2)
A4: L-003 | B4: Object to application | C4: OBJ-04 | D4: APP-044 | E4: Procurement portal | F4: Reference | I4: =IF(H4="","",H4-Settings!$B$2)
A5: L-004 | B5: Object to application | C5: OBJ-04 | D5: APP-118 | E5: Market D supplier register | F5: Reference | G5: Market D | I5: =IF(H5="","",H5-Settings!$B$2)
A6: L-005 | B6: Object to application | C6: OBJ-04 | D6: APP-077 | E6: Data platform | F6: Consumer | I6: =IF(H6="","",H6-Settings!$B$2)
A7: L-006 | B7: Object to IT component | C7: OBJ-04 | D7: ITC-009 | E7: Core ERP database, region EU | F7: Sits on | G7: EU | I7: =IF(H7="","",H7-Settings!$B$2)
A8: L-007 | B8: Object to IT component | C8: OBJ-04 | D8: ITC-041 | E8: Market E database, in-country | F8: Sits on | G8: Market E | I8: =IF(H8="","",H8-Settings!$B$2) | J8: Residency requirement, statutory
A9: L-008 | B9: Object to interface | C9: OBJ-04 | D9: INT-001 | E9: Supplier master to market portal | F9: Carried by | I9: =IF(H9="","",H9-Settings!$B$2) | J9: Event, canonical shape
A10: L-009 | B10: Object to interface | C10: OBJ-04 | D10: INT-005 | E10: Local supplier register lookup | F10: Carried by | G10: Market D | I10: =IF(H10="","",H10-Settings!$B$2) | J10: Synchronous, user is waiting
A11: L-010 | B11: Object to capability | C11: OBJ-01 | D11: CAP-004 | E11: Customer management | F11: Owns lifecycle | I11: =IF(H11="","",H11-Settings!$B$2)
A12: L-011 | B12: Object to application | C12: OBJ-01 | D12: APP-011 | E12: CRM | F12: Master | I12: =IF(H12="","",H12-Settings!$B$2)
A13: L-012 | B13: Object to application | C13: OBJ-01 | D13: APP-023 | E13: Commerce platform | F13: Consumer | I13: =IF(H13="","",H13-Settings!$B$2)
A14: L-013 | B14: Object to application | C14: OBJ-01 | D14: APP-090 | E14: Campaign tool | F14: Consumer | I14: =IF(H14="","",H14-Settings!$B$2) | J14: Asked to master it in Q1, refused, reads via API
A15: L-014 | B15: Object to IT component | C15: OBJ-01 | D15: ITC-014 | E15: CRM database, region EU | F15: Sits on | G15: EU | I15: =IF(H15="","",H15-Settings!$B$2)
A16: L-015 | B16: Object to IT component | C16: OBJ-01 | D16: ITC-052 | E16: Market G database, in-country | F16: Sits on | G16: Market G | I16: =IF(H16="","",H16-Settings!$B$2) | J16: Residency requirement
A17: L-016 | B17: Object to capability | C17: OBJ-07 | D17: CAP-018 | E17: Pricing | F17: Owns lifecycle | I17: =IF(H17="","",H17-Settings!$B$2)
A18: L-017 | B18: Object to application | C18: OBJ-07 | D18: APP-002 | E18: Core ERP | F18: Master | I18: =IF(H18="","",H18-Settings!$B$2)
A19: L-018 | B19: Object to application | C19: OBJ-07 | D19: APP-131 | E19: Pricing service, side-by-side | F19: Master | I19: =IF(H19="","",H19-Settings!$B$2) | J19: Takes mastership Q4 - two masters until then, see EXC-11
A20: L-019 | B20: Object to application | C20: OBJ-07 | D20: APP-023 | E20: Commerce platform | F20: Consumer | I20: =IF(H20="","",H20-Settings!$B$2)
A21: L-020 | B21: Object to interface | C21: OBJ-07 | D21: INT-021 | E21: Price to commerce | F21: Carried by | I21: =IF(H21="","",H21-Settings!$B$2)
A22: L-021 | B22: Object to capability | C22: OBJ-02 | D22: CAP-009 | E22: Product management | F22: Owns lifecycle | I22: =IF(H22="","",H22-Settings!$B$2)
A23: L-022 | B23: Object to application | C23: OBJ-02 | D23: APP-002 | E23: Core ERP | F23: Master | I23: =IF(H23="","",H23-Settings!$B$2)
A24: L-023 | B24: Object to application | C24: OBJ-02 | D24: APP-023 | E24: Commerce platform | F24: Consumer | I24: =IF(H24="","",H24-Settings!$B$2)
A25: L-024 | B25: Object to IT component | C25: OBJ-02 | D25: ITC-009 | E25: Core ERP database, region EU | F25: Sits on | G25: EU | I25: =IF(H25="","",H25-Settings!$B$2)
A26: L-025 | B26: Object to capability | C26: OBJ-03 | D26: CAP-022 | E26: People operations | F26: Owns lifecycle | I26: =IF(H26="","",H26-Settings!$B$2)
A27: L-026 | B27: Object to application | C27: OBJ-03 | D27: APP-055 | E27: HR system | F27: Master | I27: =IF(H27="","",H27-Settings!$B$2)
A28: L-027 | B28: Object to application | C28: OBJ-03 | D28: APP-061 | E28: Identity management | F28: Consumer | I28: =IF(H28="","",H28-Settings!$B$2)
A29: L-028 | B29: Object to IT component | C29: OBJ-03 | D29: ITC-030 | E29: HR database, per market in-country | F29: Sits on | G29: All markets | I29: =IF(H29="","",H29-Settings!$B$2) | J29: Residency requirement in every market
A30: L-029 | B30: Object to capability | C30: OBJ-05 | D30: CAP-014 | E30: Order management | F30: Owns lifecycle | I30: =IF(H30="","",H30-Settings!$B$2)
A31: L-030 | B31: Object to application | C31: OBJ-05 | D31: APP-002 | E31: Core ERP | F31: Master | I31: =IF(H31="","",H31-Settings!$B$2)
A32: L-031 | B32: Object to interface | C32: OBJ-05 | D32: INT-002 | E32: Sales orders from web shop | F32: Carried by | I32: =IF(H32="","",H32-Settings!$B$2)
A33: L-032 | B33: Object to capability | C33: OBJ-06 | D33: CAP-031 | E33: Source to contract | F33: Owns lifecycle | I33: =IF(H33="","",H33-Settings!$B$2)
A34: L-033 | B34: Object to application | C34: OBJ-06 | D34: APP-101 | E34: Contract system | F34: Master | I34: =IF(H34="","",H34-Settings!$B$2)
A35: L-034 | B35: Object to IT component | C35: OBJ-06 | D35: ITC-066 | E35: Market F store, in-country | F35: Sits on | G35: Market F | I35: =IF(H35="","",H35-Settings!$B$2) | J35: See EXC-10
A36: L-035 | B36: Object to capability | C36: OBJ-08 | D36: CAP-041 | E36: Finance operations | F36: Owns lifecycle | I36: =IF(H36="","",H36-Settings!$B$2)
A37: L-036 | B37: Object to application | C37: OBJ-08 | D37: APP-002 | E37: Core ERP | F37: Master | I37: =IF(H37="","",H37-Settings!$B$2)
A38: L-037 | B38: Object to capability | C38: OBJ-09 | D38: CAP-050 | E38: Store operations | F38: Owns lifecycle | I38: =IF(H38="","",H38-Settings!$B$2)
A39: L-038 | B39: Object to application | C39: OBJ-09 | D39: APP-002 | E39: Core ERP | F39: Master | I39: =IF(H39="","",H39-Settings!$B$2)
A40: L-039 | B40: Object to capability | C40: OBJ-10 | D40: CAP-027 | E40: Marketing | F40: Owns lifecycle | I40: =IF(H40="","",H40-Settings!$B$2)
...

Sheet Exceptions
A1: Ref | B1: Raised | C1: Obj ID | D1: What is being deviated from | E1: Reason | F1: Approved by | G1: Expiry | H1: Days to expiry | I1: Status
A2: EXC-08 | B2: 45944 | C2: OBJ-01 | D2: One system of record - read-only customer copy in the reporting store | E2: Month-end close latency | F2: Data architect | G2: 46309 | H2: =IF(G2="","",G2-Settings!$B$2) | I2: Open
A3: EXC-09 | B3: 46042 | C3: OBJ-04 | D3: Market D keeps a local supplier register as a reference copy | E3: Regulator approved the local tool; partner contract runs to 2026 | F3: Architecture board | G3: 46387 | H3: =IF(G3="","",G3-Settings!$B$2) | I3: Open
A4: EXC-10 | B4: 46084 | C4: OBJ-06 | D4: Contract data replicated to market F in-country store | E4: Residency requirement, statutory | F4: Compliance lead | H4: =IF(G4="","",G4-Settings!$B$2) | I4: Open
A5: EXC-11 | B5: 46182 | C5: OBJ-07 | D5: Dual-write window during the pricing mastership move | E5: Cutover requires both systems writing for eight weeks | F5: Architecture board | G5: 46380 | H5: =IF(G5="","",G5-Settings!$B$2) | I5: Open
A6: EXC-12 | B6: 45874 | C6: OBJ-10 | D6: Promotion mastered in the promotion tool rather than the core | E6: Tool predates the programme; migration in wave three | F6: Architecture board | G6: 46142 | H6: =IF(G6="","",G6-Settings!$B$2) | I6: Open
H7: =IF(G7="","",G7-Settings!$B$2)
H8: =IF(G8="","",G8-Settings!$B$2)
H9: =IF(G9="","",G9-Settings!$B$2)
H10: =IF(G10="","",G10-Settings!$B$2)
H11: =IF(G11="","",G11-Settings!$B$2)
H12: =IF(G12="","",G12-Settings!$B$2)
H13: =IF(G13="","",G13-Settings!$B$2)
H14: =IF(G14="","",G14-Settings!$B$2)
H15: =IF(G15="","",G15-Settings!$B$2)
H16: =IF(G16="","",G16-Settings!$B$2)
H17: =IF(G17="","",G17-Settings!$B$2)
H18: =IF(G18="","",G18-Settings!$B$2)
... H101: =IF(G101="","",G101-Settings!$B$2)
A103: A dual-write window without a written expiry is how three weeks becomes two years. EXC-11 exists for exactly that reason.

Sheet Derived views
A1: Derived views
A2: Nothing here is typed. Everything computes from Objects, Attributes and Links.
A4: The three report lines
A5: Domain objects | B5: =COUNTA(Objects!$A$2:$A$61) | D5: Twenty to forty at group level
A6: Objects with a single confirmed master | B6: =COUNTIF(C13:C24,"=1") | D6: Exactly one master link. Contradictions and gaps are excluded
A7: Objects attested this quarter | B7: =COUNTIFS(Objects!$A$2:$A$61,"<>",Objects!$P$2:$P$61,"ok") | D7: The leading indicator for the whole model
A8: Oldest attestation (days) | B8: =IFERROR(MAX(Objects!$O$2:$O$61),"") | D8: An object unattested for fourteen months has an owner who stopped reading
A10: The contradiction report - objects with more than one master
A11: A live incident waiting to happen. This is the single most valuable query in the file.
A12: Obj ID | B12: Name | C12: Masters | D12: Verdict
A13: =IF(Objects!A2="","",Objects!A2) | B13: =IF(A13="","",Objects!B2) | C13: =IF(A13="","",COUNTIFS(Links!$C$2:$C$601,A13,Links!$F$2:$F$601,"Master")) | D13: =IF(A13="","",IF(C13>1,"TWO MASTERS - resolve or register an exception",IF(C13=0,"no master recorded","ok")))
A14: =IF(Objects!A3="","",Objects!A3) | B14: =IF(A14="","",Objects!B3) | C14: =IF(A14="","",COUNTIFS(Links!$C$2:$C$601,A14,Links!$F$2:$F$601,"Master")) | D14: =IF(A14="","",IF(C14>1,"TWO MASTERS - resolve or register an exception",IF(C14=0,"no master recorded","ok")))
A15: =IF(Objects!A4="","",Objects!A4) | B15: =IF(A15="","",Objects!B4) | C15: =IF(A15="","",COUNTIFS(Links!$C$2:$C$601,A15,Links!$F$2:$F$601,"Master")) | D15: =IF(A15="","",IF(C15>1,"TWO MASTERS - resolve or register an exception",IF(C15=0,"no master recorded","ok")))
A16: =IF(Objects!A5="","",Objects!A5) | B16: =IF(A16="","",Objects!B5) | C16: =IF(A16="","",COUNTIFS(Links!$C$2:$C$601,A16,Links!$F$2:$F$601,"Master")) | D16: =IF(A16="","",IF(C16>1,"TWO MASTERS - resolve or register an exception",IF(C16=0,"no master recorded","ok")))
A17: =IF(Objects!A6="","",Objects!A6) | B17: =IF(A17="","",Objects!B6) | C17: =IF(A17="","",COUNTIFS(Links!$C$2:$C$601,A17,Links!$F$2:$F$601,"Master")) | D17: =IF(A17="","",IF(C17>1,"TWO MASTERS - resolve or register an exception",IF(C17=0,"no master recorded","ok")))
A18: =IF(Objects!A7="","",Objects!A7) | B18: =IF(A18="","",Objects!B7) | C18: =IF(A18="","",COUNTIFS(Links!$C$2:$C$601,A18,Links!$F$2:$F$601,"Master")) | D18: =IF(A18="","",IF(C18>1,"TWO MASTERS - resolve or register an exception",IF(C18=0,"no master recorded","ok")))
A19: =IF(Objects!A8="","",Objects!A8) | B19: =IF(A19="","",Objects!B8) | C19: =IF(A19="","",COUNTIFS(Links!$C$2:$C$601,A19,Links!$F$2:$F$601,"Master")) | D19: =IF(A19="","",IF(C19>1,"TWO MASTERS - resolve or register an exception",IF(C19=0,"no master recorded","ok")))
A20: =IF(Objects!A9="","",Objects!A9) | B20: =IF(A20="","",Objects!B9) | C20: =IF(A20="","",COUNTIFS(Links!$C$2:$C$601,A20,Links!$F$2:$F$601,"Master")) | D20: =IF(A20="","",IF(C20>1,"TWO MASTERS - resolve or register an exception",IF(C20=0,"no master recorded","ok")))
A21: =IF(Objects!A10="","",Objects!A10) | B21: =IF(A21="","",Objects!B10) | C21: =IF(A21="","",COUNTIFS(Links!$C$2:$C$601,A21,Links!$F$2:$F$601,"Master")) | D21: =IF(A21="","",IF(C21>1,"TWO MASTERS - resolve or register an exception",IF(C21=0,"no master recorded","ok")))
A22: =IF(Objects!A11="","",Objects!A11) | B22: =IF(A22="","",Objects!B11) | C22: =IF(A22="","",COUNTIFS(Links!$C$2:$C$601,A22,Links!$F$2:$F$601,"Master")) | D22: =IF(A22="","",IF(C22>1,"TWO MASTERS - resolve or register an exception",IF(C22=0,"no master recorded","ok")))
A23: =IF(Objects!A12="","",Objects!A12) | B23: =IF(A23="","",Objects!B12) | C23: =IF(A23="","",COUNTIFS(Links!$C$2:$C$601,A23,Links!$F$2:$F$601,"Master")) | D23: =IF(A23="","",IF(C23>1,"TWO MASTERS - resolve or register an exception",IF(C23=0,"no master recorded","ok")))
A24: =IF(Objects!A13="","",Objects!A13) | B24: =IF(A24="","",Objects!B13) | C24: =IF(A24="","",COUNTIFS(Links!$C$2:$C$601,A24,Links!$F$2:$F$601,"Master")) | D24: =IF(A24="","",IF(C24>1,"TWO MASTERS - resolve or register an exception",IF(C24=0,"no master recorded","ok")))
A27: Residency answer - where does an object physically sit
A28: Type an object ID in the yellow cell. The count comes from the object-to-IT-component join; filter the Links sheet for the detail.
A29: Object ID | B29: OBJ-04
A30: IT components holding it | B30: =COUNTIFS(Links!$C$2:$C$601,$B$29,Links!$B$2:$B$601,"Object to IT component") | D30: This row is the difference between a four-day answer and a six-week investigation
A31: Applications touching it | B31: =COUNTIFS(Links!$C$2:$C$601,$B$29,Links!$B$2:$B$601,"Object to application")
A32: Interfaces carrying it | B32: =COUNTIFS(Links!$C$2:$C$601,$B$29,Links!$B$2:$B$601,"Object to interface")
A33: Reference copies with an expiry | B33: =COUNTIFS(Links!$C$2:$C$601,$B$29,Links!$F$2:$F$601,"Reference")
A34: Open exceptions | B34: =COUNTIFS(Exceptions!$C$2:$C$101,$B$29,Exceptions!$I$2:$I$101,"Open")
A35: Jurisdiction-scoped attributes | B35: =COUNTIFS(Attributes!$A$2:$A$401,$B$29,Attributes!$C$2:$C$401,"Jurisdiction-scoped") | D35: Also the localization backlog, and the honest answer to how much of a programme is legal requirement
A38: Hygiene checks
A39: Objects over the count ceiling | B39: =MAX(0,COUNTA(Objects!$A$2:$A$61)-Settings!$B$4) | D39: Argue about it rather than silently exceeding it
A40: Objects with no master recorded | B40: =COUNTIFS(Objects!$A$2:$A$61,"<>",Objects!$I$2:$I$61,"") | D40: The most useful gap in the file
A41: Objects with no owning capability | B41: =COUNTIFS(Objects!$A$2:$A$61,"<>",Objects!$F$2:$F$61,"") | D41: Ownership that is a name in a field rather than structural
A42: Objects with no boundary line | B42: =COUNTIFS(Objects!$A$2:$A$61,"<>",Objects!$E$2:$E$61,"") | D42: The field everybody skips, and the one that closes disputes
A43: Objects with no aliases | B43: =COUNTIFS(Objects!$A$2:$A$61,"<>",Objects!$C$2:$C$61,"") | D43: The other field everybody skips
A44: Stale objects | B44: =COUNTIF(Objects!$P$2:$P$61,"STALE") | D44: Findings, routed to a person with a due date
A45: Contested objects | B45: =COUNTIF(Objects!$M$2:$M$61,"Contested") | D45: Board agenda, not a design forum item
A46: Links with no role | B46: =COUNTIFS(Links!$A$2:$A$601,"<>",Links!$F$2:$F$601,"") | D46: A link without a role tells you nothing you did not suspect
...
